second error! 2018-10-16 15:03:10.686272  return code : 1 Status : FAIL  None  b'2018-10-16 15:03:07.120491: I tensorflow/core/platform/cpu_feature_guard.cc:141] Your CPU supports instructions that this TensorFlow binary was not compiled to use: AVX2 FMA\nUsing TensorFlow backend.\nTraceback (most recent call last):\n  File "./hwang_main/subprocess/keras_model.py", line 23, in <module>\n    pre = model.predict_classes(ss)\n  File "/usr/lib64/python3.6/site-packages/keras/engine/sequential.py", line 267, in predict_classes\n    proba = self.predict(x, batch_size=batch_size, verbose=verbose)\n  File "/usr/lib64/python3.6/site-packages/keras/engine/training.py", line 1169, in predict\n    steps=steps)\n  File "/usr/lib64/python3.6/site-packages/keras/engine/training_arrays.py", line 294, in predict_loop\n    batch_outs = f(ins_batch)\n  File "/usr/lib64/python3.6/site-packages/keras/backend/tensorflow_backend.py", line 2715, in __call__\n    return self._call(inputs)\n  File "/usr/lib64/python3.6/site-packages/keras/backend/tensorflow_backend.py", line 2675, in _call\n    fetched = self._callable_fn(*array_vals)\n  File "/usr/lib/python3.6/site-packages/tensorflow/python/client/session.py", line 1399, in __call__\n    run_metadata_ptr)\n  File "/usr/lib/python3.6/site-packages/tensorflow/python/framework/errors_impl.py", line 526, in __exit__\n    c_api.TF_GetCode(self.status.status))\ntensorflow.python.framework.errors_impl.InvalidArgumentError: indices[0,477] = 6395 is not in [0, 5000)\n\t [[{{node embedding_1/embedding_lookup}} = GatherV2[Taxis=DT_INT32, Tindices=DT_INT32, Tparams=DT_FLOAT, _device="/job:localhost/replica:0/task:0/device:CPU:0"](embedding_1/embeddings/read, embedding_1/Cast, embedding_1/embedding_lookup/axis)]]\n'
second error! 2018-10-17 08:59:44.728584  return code : 1 Status : FAIL  None  b'2018-10-17 08:59:41.892506: I tensorflow/core/platform/cpu_feature_guard.cc:141] Your CPU supports instructions that this TensorFlow binary was not compiled to use: AVX2 FMA\nUsing TensorFlow backend.\nTraceback (most recent call last):\n  File "./hwang_main/subprocess/keras_model.py", line 26, in <module>\n    with open(\'./hwang_main/subprocess/jin4.txt\', \'w\', encoding=\'utf8\') as f: f.wrtie(str(pre)) \nAttributeError: \'_io.TextIOWrapper\' object has no attribute \'wrtie\'\n'
second error! 2018-10-17 09:30:40.650763  return code : 1 Status : FAIL  None  b'2018-10-17 09:30:36.609192: I tensorflow/core/platform/cpu_feature_guard.cc:141] Your CPU supports instructions that this TensorFlow binary was not compiled to use: AVX2 FMA\nUsing TensorFlow backend.\nTraceback (most recent call last):\n  File "./hwang_main/subprocess/keras_model.py", line 26, in <module>\n    with open(\'./hwang_main/subprocess/jin4.txt\', \'w\', encoding=\'utf8\') as f: f.wrtie(str(pre)) \nAttributeError: \'_io.TextIOWrapper\' object has no attribute \'wrtie\'\n'
second error! 2018-10-17 09:36:53.592729  return code : 1 Status : FAIL  None  b'2018-10-17 09:36:50.215223: I tensorflow/core/platform/cpu_feature_guard.cc:141] Your CPU supports instructions that this TensorFlow binary was not compiled to use: AVX2 FMA\nUsing TensorFlow backend.\nTraceback (most recent call last):\n  File "./hwang_main/subprocess/keras_model.py", line 23, in <module>\n    with open(\'./hwang_main/subprocess/jin4.txt\', \'w\', encoding=\'utf8\') as f: f.wrtie(str(pre)) \nAttributeError: \'_io.TextIOWrapper\' object has no attribute \'wrtie\'\n'
second error! 2018-10-17 09:36:58.655009  return code : 1 Status : FAIL  None  b'2018-10-17 09:36:56.156741: I tensorflow/core/platform/cpu_feature_guard.cc:141] Your CPU supports instructions that this TensorFlow binary was not compiled to use: AVX2 FMA\nUsing TensorFlow backend.\nTraceback (most recent call last):\n  File "./hwang_main/subprocess/keras_model.py", line 23, in <module>\n    with open(\'./hwang_main/subprocess/jin4.txt\', \'w\', encoding=\'utf8\') as f: f.wrtie(str(pre)) \nAttributeError: \'_io.TextIOWrapper\' object has no attribute \'wrtie\'\n'
second error! 2018-10-17 09:38:37.354424  return code : 1 Status : FAIL  None  b'2018-10-17 09:38:34.798144: I tensorflow/core/platform/cpu_feature_guard.cc:141] Your CPU supports instructions that this TensorFlow binary was not compiled to use: AVX2 FMA\nUsing TensorFlow backend.\nTraceback (most recent call last):\n  File "./hwang_main/subprocess/keras_model.py", line 23, in <module>\n    with open(\'./hwang_main/subprocess/jin4.txt\', \'w\', encoding=\'utf8\') as f: f.wrtie(str(pre)) \nAttributeError: \'_io.TextIOWrapper\' object has no attribute \'wrtie\'\n'
second error! 2018-10-23 01:34:20.801345  return code : 1 Status : FAIL  None  b'2018-10-23 01:34:16.730358: I tensorflow/core/platform/cpu_feature_guard.cc:141] Your CPU supports instructions that this TensorFlow binary was not compiled to use: AVX2 FMA\nUsing TensorFlow backend.\nTraceback (most recent call last):\n  File "./hwang_main/subprocess/keras_model.py", line 23, in <module>\n    with open(\'./hwang_main/subprocess/jin4.txt\', \'w\', encoding=\'utf8\') as f: f.wrtie(str(pre)) \nAttributeError: \'_io.TextIOWrapper\' object has no attribute \'wrtie\'\n'
second error! 2018-10-23 01:35:05.597000  return code : 1 Status : FAIL  None  b'2018-10-23 01:35:01.524444: I tensorflow/core/platform/cpu_feature_guard.cc:141] Your CPU supports instructions that this TensorFlow binary was not compiled to use: AVX2 FMA\nUsing TensorFlow backend.\nTraceback (most recent call last):\n  File "./hwang_main/subprocess/keras_model.py", line 23, in <module>\n    with open(\'./hwang_main/subprocess/jin4.txt\', \'w\', encoding=\'utf8\') as f: f.wrtie(str(pre)) \nAttributeError: \'_io.TextIOWrapper\' object has no attribute \'wrtie\'\n'
second error! 2018-10-23 01:39:06.528480  return code : 1 Status : FAIL  None  b'2018-10-23 01:39:03.092807: I tensorflow/core/platform/cpu_feature_guard.cc:141] Your CPU supports instructions that this TensorFlow binary was not compiled to use: AVX2 FMA\nUsing TensorFlow backend.\nTraceback (most recent call last):\n  File "./hwang_main/subprocess/keras_model.py", line 23, in <module>\n    with open(\'./hwang_main/subprocess/jin4.txt\', \'w\', encoding=\'utf8\') as f: f.wrtie(str(pre)) \nAttributeError: \'_io.TextIOWrapper\' object has no attribute \'wrtie\'\n'
second error! 2018-10-23 01:40:33.280120  return code : 1 Status : FAIL  None  b'2018-10-23 01:40:29.749887: I tensorflow/core/platform/cpu_feature_guard.cc:141] Your CPU supports instructions that this TensorFlow binary was not compiled to use: AVX2 FMA\nUsing TensorFlow backend.\nTraceback (most recent call last):\n  File "./hwang_main/subprocess/keras_model.py", line 23, in <module>\n    with open(\'./hwang_main/subprocess/jin4.txt\', \'w\', encoding=\'utf8\') as f: f.wrtie(str(pre)) \nAttributeError: \'_io.TextIOWrapper\' object has no attribute \'wrtie\'\n'
second error! 2018-10-23 01:45:13.055856  return code : 1 Status : FAIL  None  b'2018-10-23 01:45:10.640870: I tensorflow/core/platform/cpu_feature_guard.cc:141] Your CPU supports instructions that this TensorFlow binary was not compiled to use: AVX2 FMA\nUsing TensorFlow backend.\nTraceback (most recent call last):\n  File "./hwang_main/subprocess/keras_model.py", line 23, in <module>\n    with open(\'./hwang_main/subprocess/jin4.txt\', \'w\', encoding=\'utf8\') as f: f.wrtie(str(pre)) \nAttributeError: \'_io.TextIOWrapper\' object has no attribute \'wrtie\'\n'
